{"uuid": "586e2c4a-405f-4e78-a63d-79e94f3efc88", "children": ["ed2b820d-e959-4c06-b53f-e41ed0e3b012", "43af5295-10b5-48f2-9c20-691474859b65", "abce7d72-92c6-49c1-a5db-2ef13b23e53e"], "befores": [{"name": "driver", "status": "broken", "statusDetails": {"message": "selenium.common.exceptions.WebDriverException: Message: 'chromedriver' executable needs to be in PATH. Please see https://chromedriver.chromium.org/home\n\n", "trace": "  File \"/usr/local/lib/python3.12/site-packages/pluggy/_callers.py\", line 80, in _multicall\n    res = hook_impl.function(*args)\n          ^^^^^^^^^^^^^^^^^^^^^^^^^\n  File \"/usr/local/lib/python3.12/site-packages/_pytest/fixtures.py\", line 1123, in pytest_fixture_setup\n    result = call_fixture_func(fixturefunc, request, kwargs)\n             ^^^^^^^^^^^^^^^^^^^^^^^^^^^^^^^^^^^^^^^^^^^^^^^\n  File \"/usr/local/lib/python3.12/site-packages/_pytest/fixtures.py\", line 895, in call_fixture_func\n    fixture_result = next(generator)\n                     ^^^^^^^^^^^^^^^\n  File \"/usr/workspace/conftest.py\", line 25, in driver\n    driver = webdriver.Chrome(service=ser, options=options)\n             ^^^^^^^^^^^^^^^^^^^^^^^^^^^^^^^^^^^^^^^^^^^^^^\n  File \"/usr/local/lib/python3.12/site-packages/selenium/webdriver/chrome/webdriver.py\", line 49, in __init__\n    super().__init__(\n  File \"/usr/local/lib/python3.12/site-packages/selenium/webdriver/chromium/webdriver.py\", line 51, in __init__\n    self.service.start()\n  File \"/usr/local/lib/python3.12/site-packages/selenium/webdriver/common/service.py\", line 93, in start\n    self._start_process(self._path)\n  File \"/usr/local/lib/python3.12/site-packages/selenium/webdriver/common/service.py\", line 209, in _start_process\n    raise WebDriverException(\n"}, "start": 1718678598214, "stop": 1718678598215}], "start": 1718678598214, "stop": 1718678598259}