{"uuid": "299f20e6-4078-46a9-8625-c02d5801f2c2", "children": ["18cc1d8e-5b54-4f63-8138-2a2b84964b7e", "a6817182-61de-4cf2-8f11-1a53436b59c8", "ae2a1013-e5e8-45b7-8716-0460a4fe245a"], "befores": [{"name": "driver", "status": "broken", "statusDetails": {"message": "selenium.common.exceptions.WebDriverException: Message: unknown error: Chrome failed to start: exited abnormally.\n  (unknown error: DevToolsActivePort file doesn't exist)\n  (The process started from chrome location /usr/lib/chromium/chrome is no longer running, so ChromeDriver is assuming that Chrome has crashed.)\n\n", "trace": "  File \"/usr/local/lib/python3.12/site-packages/pluggy/_callers.py\", line 80, in _multicall\n    res = hook_impl.function(*args)\n          ^^^^^^^^^^^^^^^^^^^^^^^^^\n  File \"/usr/local/lib/python3.12/site-packages/_pytest/fixtures.py\", line 1123, in pytest_fixture_setup\n    result = call_fixture_func(fixturefunc, request, kwargs)\n             ^^^^^^^^^^^^^^^^^^^^^^^^^^^^^^^^^^^^^^^^^^^^^^^\n  File \"/usr/local/lib/python3.12/site-packages/_pytest/fixtures.py\", line 895, in call_fixture_func\n    fixture_result = next(generator)\n                     ^^^^^^^^^^^^^^^\n  File \"/usr/workspace/conftest.py\", line 25, in driver\n    driver = webdriver.Chrome(options=options)\n             ^^^^^^^^^^^^^^^^^^^^^^^^^^^^^^^^^\n  File \"/usr/local/lib/python3.12/site-packages/selenium/webdriver/chrome/webdriver.py\", line 49, in __init__\n    super().__init__(\n  File \"/usr/local/lib/python3.12/site-packages/selenium/webdriver/chromium/webdriver.py\", line 54, in __init__\n    super().__init__(\n  File \"/usr/local/lib/python3.12/site-packages/selenium/webdriver/remote/webdriver.py\", line 206, in __init__\n    self.start_session(capabilities)\n  File \"/usr/local/lib/python3.12/site-packages/selenium/webdriver/remote/webdriver.py\", line 291, in start_session\n    response = self.execute(Command.NEW_SESSION, caps)[\"value\"]\n               ^^^^^^^^^^^^^^^^^^^^^^^^^^^^^^^^^^^^^^^\n  File \"/usr/local/lib/python3.12/site-packages/selenium/webdriver/remote/webdriver.py\", line 346, in execute\n    self.error_handler.check_response(response)\n  File \"/usr/local/lib/python3.12/site-packages/selenium/webdriver/remote/errorhandler.py\", line 245, in check_response\n    raise exception_class(message, screen, stacktrace)\n"}, "start": 1718679152824, "stop": 1718679153509}], "start": 1718679152824, "stop": 1718679153539}