{"uuid": "9e6ecf7c-e0f8-4896-9c15-5fc9b9405210", "children": ["4f8b629d-6b48-45b5-9158-65ef74953f85", "5d7c21f8-766e-4267-a6b1-b16623be34e3", "81666b6d-6939-4ffb-abaf-d30a7fc5dc81"], "befores": [{"name": "driver", "status": "broken", "statusDetails": {"message": "selenium.common.exceptions.WebDriverException: Message: 'chromedriver' executable needs to be in PATH. Please see https://chromedriver.chromium.org/home\n\n", "trace": "  File \"/usr/local/lib/python3.12/site-packages/pluggy/_callers.py\", line 80, in _multicall\n    res = hook_impl.function(*args)\n          ^^^^^^^^^^^^^^^^^^^^^^^^^\n  File \"/usr/local/lib/python3.12/site-packages/_pytest/fixtures.py\", line 1123, in pytest_fixture_setup\n    result = call_fixture_func(fixturefunc, request, kwargs)\n             ^^^^^^^^^^^^^^^^^^^^^^^^^^^^^^^^^^^^^^^^^^^^^^^\n  File \"/usr/local/lib/python3.12/site-packages/_pytest/fixtures.py\", line 895, in call_fixture_func\n    fixture_result = next(generator)\n                     ^^^^^^^^^^^^^^^\n  File \"/usr/workspace/conftest.py\", line 26, in driver\n    driver = webdriver.Chrome(service=ser, options=options)\n             ^^^^^^^^^^^^^^^^^^^^^^^^^^^^^^^^^^^^^^^^^^^^^^\n  File \"/usr/local/lib/python3.12/site-packages/selenium/webdriver/chrome/webdriver.py\", line 49, in __init__\n    super().__init__(\n  File \"/usr/local/lib/python3.12/site-packages/selenium/webdriver/chromium/webdriver.py\", line 51, in __init__\n    self.service.start()\n  File \"/usr/local/lib/python3.12/site-packages/selenium/webdriver/common/service.py\", line 93, in start\n    self._start_process(self._path)\n  File \"/usr/local/lib/python3.12/site-packages/selenium/webdriver/common/service.py\", line 209, in _start_process\n    raise WebDriverException(\n"}, "start": 1718677454218, "stop": 1718677454218}], "start": 1718677454218, "stop": 1718677454263}