{"uuid": "e0bed86b-4d30-41cf-ba90-b569cdf9b9fd", "children": ["1be05685-149b-4d0e-89f3-a945f1c90ba5", "7e1ef2f7-bc5f-44ec-a975-671d0639aa3a", "db1326f2-4f42-40a9-bbc0-7c810c4dd587"], "befores": [{"name": "driver", "status": "broken", "statusDetails": {"message": "selenium.common.exceptions.WebDriverException: Message: 'chromedriver' executable needs to be in PATH. Please see https://chromedriver.chromium.org/home\n\n", "trace": "  File \"/usr/local/lib/python3.12/site-packages/pluggy/_callers.py\", line 80, in _multicall\n    res = hook_impl.function(*args)\n          ^^^^^^^^^^^^^^^^^^^^^^^^^\n  File \"/usr/local/lib/python3.12/site-packages/_pytest/fixtures.py\", line 1123, in pytest_fixture_setup\n    result = call_fixture_func(fixturefunc, request, kwargs)\n             ^^^^^^^^^^^^^^^^^^^^^^^^^^^^^^^^^^^^^^^^^^^^^^^\n  File \"/usr/local/lib/python3.12/site-packages/_pytest/fixtures.py\", line 895, in call_fixture_func\n    fixture_result = next(generator)\n                     ^^^^^^^^^^^^^^^\n  File \"/usr/workspace/conftest.py\", line 25, in driver\n    service.start()\n  File \"/usr/local/lib/python3.12/site-packages/selenium/webdriver/common/service.py\", line 93, in start\n    self._start_process(self._path)\n  File \"/usr/local/lib/python3.12/site-packages/selenium/webdriver/common/service.py\", line 209, in _start_process\n    raise WebDriverException(\n"}, "start": 1718832558658, "stop": 1718832558660}], "start": 1718832558658, "stop": 1718832558705}