{"uuid": "41f431f7-dd18-403d-a0ae-555e9a10d814", "children": ["0c3cbb52-5bf8-4e20-8a58-929e10d242e5", "00fed4bb-7c6c-41fe-a36e-118294fc24af", "b878ac79-7633-4ee9-ad94-5d2ff6ef0b5c"], "befores": [{"name": "driver", "status": "broken", "statusDetails": {"message": "selenium.common.exceptions.WebDriverException: Message: 'chromedriver' executable needs to be in PATH. Please see https://chromedriver.chromium.org/home\n\n", "trace": "  File \"/usr/local/lib/python3.12/site-packages/pluggy/_callers.py\", line 80, in _multicall\n    res = hook_impl.function(*args)\n          ^^^^^^^^^^^^^^^^^^^^^^^^^\n  File \"/usr/local/lib/python3.12/site-packages/_pytest/fixtures.py\", line 1123, in pytest_fixture_setup\n    result = call_fixture_func(fixturefunc, request, kwargs)\n             ^^^^^^^^^^^^^^^^^^^^^^^^^^^^^^^^^^^^^^^^^^^^^^^\n  File \"/usr/local/lib/python3.12/site-packages/_pytest/fixtures.py\", line 895, in call_fixture_func\n    fixture_result = next(generator)\n                     ^^^^^^^^^^^^^^^\n  File \"/usr/workspace/conftest.py\", line 26, in driver\n    driver = webdriver.Chrome(service=ser, options=options)\n             ^^^^^^^^^^^^^^^^^^^^^^^^^^^^^^^^^^^^^^^^^^^^^^\n  File \"/usr/local/lib/python3.12/site-packages/selenium/webdriver/chrome/webdriver.py\", line 49, in __init__\n    super().__init__(\n  File \"/usr/local/lib/python3.12/site-packages/selenium/webdriver/chromium/webdriver.py\", line 51, in __init__\n    self.service.start()\n  File \"/usr/local/lib/python3.12/site-packages/selenium/webdriver/common/service.py\", line 93, in start\n    self._start_process(self._path)\n  File \"/usr/local/lib/python3.12/site-packages/selenium/webdriver/common/service.py\", line 209, in _start_process\n    raise WebDriverException(\n"}, "start": 1718677842272, "stop": 1718677842273}], "start": 1718677842272, "stop": 1718677842320}